function* helloWorldGenerator() {
  yield 'hello';
  yield 'world';
  return 'ending';
}

var hw = helloWorldGenerator();
hw.next()
// { value: 'hello', done: false }

hw.next()
// { value: 'world', done: false }

hw.next()
// { value: 'ending', done: true }

hw.next()
// { value: undefined, done: true }


//上面代码的最后一行，Generator函数体外，使用指针对象的throw方法抛出的错误，可以被函数体内的try ...catch代码块捕获。这意味着，出错的代码与处理错误的代码，实现了时间和空间上的分离，这对于异步编程无疑是很重要的。
function* gen(x){
  try {
    var y = yield x + 2;
  } catch (e){
    console.log(e);
  }
  return y;
}

var g = gen(1);
g.next();
g.throw('出错了');
// 出错了