var getJSON = function(url) {
  var promise = new Promise(function(resolve, reject){
    var client = new XMLHttpRequest();
    client.open("GET", url);
    client.onreadystatechange = handler;
    client.responseType = "json";
    client.setRequestHeader("Accept", "application/json");
    client.send();

    function handler() {
      if ( this.readyState !== 4 ) {
        return;
      }
      if (this.status === 200) {
        resolve(this.response);
      } else {
        reject(new Error(this.statusText));
      }
    };
  });

  return promise;
};

getJSON("/posts.json").then(function(json) {
  console.log('Contents: ' + json);
}, function(error) {
  console.error('出错了', error);
});

//上面代码中，p1是一个Promise，3秒之后变为rejected。p2的状态由p1决定，1秒之后，p2调用resolve方法，但是此时p1的状态还没有改变，因此p2的状态也不会变。又过了2秒，p1变为rejected，p2也跟着变为rejected。

var p1 = new Promise(function (resolve, reject) {
  setTimeout(() => reject(new Error('fail')), 3000)
})
var p2 = new Promise(function (resolve, reject) {
  setTimeout(() => resolve(p1), 1000)
})
p2.then(result => console.log(result))
p2.catch(error => console.log(error))
// Error: fail

getJSON("/post/1.json").then(function(post) {
  return getJSON(post.commentURL);
}).then(function funcA(comments) {
  console.log("Resolved: ", comments);
}, function funcB(err){
  console.log("Rejected: ", err);
});

//上面代码中，第一个then方法指定的回调函数，返回的是另一个Promise对象。这时，第二个then方法指定的回调函数，就会等待这个新的Promise对象状态发生变化。如果变为Resolved，就调用funcA，如果状态变为Rejected，就调用funcB


//Promise.prototype.catch方法是.then(null, rejection)的别名，用于指定发生错误时的回调函数。

getJSON("/posts.json").then(function(posts) {
  // ...
}).catch(function(error) {
  // 处理前一个回调函数运行时发生的错误
  console.log('发生错误！', error);
});

// 写法一
var promise = new Promise(function(resolve, reject) {
  try {
    throw new Error('test');
  } catch(e) {
    reject(e);
  }
});
promise.catch(function(error) {
  console.log(error);
});

// 写法二
var promise = new Promise(function(resolve, reject) {
  reject(new Error('test'));
});
promise.catch(function(error) {
  console.log(error);
});